<robot name="test_robot" xmlns:xacro="http://ros.org/wiki/xacro">

	<link name = "isocenter">
	<inertial>
      <origin rpy="0 0 0" xyz="0 0 0"/>
      <mass value="0.0"/>
      <inertia ixx="1" ixy="0" ixz="0" iyy="1" iyz="0" izz="1"/>
    </inertial>
    <visual>
      <origin rpy="0 0 0" xyz="0 0 0"/>
      <geometry>
		<box size="0.001 0.001 0.001"/>
	</geometry>
		<material name="red">
        <color rgba="1 0 0 1"/>
      </material>
    </visual>
    <!--<collision>
      <origin rpy="0 0 0" xyz="0 0 0"/>
      <geometry>
         <box size="0.001 0.001 0.001"/>
      </geometry>
    </collision>-->
  </link>

	<link name="base">
    <contact>
      <lateral_friction value="1.0"/>
      <rolling_friction value="0.0"/>
      <contact_cfm value="1.0"/>
      <contact_erp value="1.0"/>
    </contact>
    <inertial>
      <origin rpy="0 0 0"  xyz="0.000000 0 0"/>
      <mass value="0.0"/>
      <inertia ixx="1" ixy="0" ixz="0" iyy="1" iyz="0" izz="1"/>
    </inertial>
    <visual>
      <origin rpy="1.5708 0 0"  xyz="0 0 0"/>
      <geometry>
        <mesh filename="pps_leoni/pied.obj" scale="1 1 1"/>
      </geometry>
      <material name="white">
        <color rgba="1 1 1 1"/>
      </material>
    </visual>
	    <collision>
      <origin rpy="1.5708 0 0"  xyz="0.000000 0 0"/>
      <geometry>
         <mesh filename="pps_leoni/pied.obj" scale="1 1 1"/>
      </geometry>
    </collision>
  </link>

	<link name="A1">
    <contact>
		<lateral_friction value="1.0"/>
		<rolling_friction value = "101"/>
		<contact_cfm value="0.0"/>
		<contact_erp value="1.0"/>
		<kd value ="1.0"/>
	</contact>
    <inertial>
      <origin rpy="0 0 0" xyz="-55.0 0 0"/>
      <mass value="0.5"/>
      <inertia ixx="1" ixy="0" ixz="0" iyy="1" iyz="0" izz="1"/>
    </inertial>
    <visual>
      <origin rpy=" 1.5708 0 0" xyz="0 0 0"/>
      <geometry>
        <mesh filename="pps_leoni/bras1.obj" scale="1 1 1"/>
      </geometry>
      <material name="white">
        <color rgba="1 1 1 1"/>
      </material>
    </visual>
    <collision>
      <origin rpy="1.5708 0 0" xyz="0 0 0"/>
      <geometry>
         <mesh filename="pps_leoni/bras1.obj" scale="1 1 1"/>
      </geometry>
    </collision>
  </link>
	<link name="A2">
    <contact>
      <lateral_friction value="1.0"/>
      <rolling_friction value="0.0"/>
      <contact_cfm value="0.0"/>
      <contact_erp value="1.0"/>
      <kd value ="1.0"/>
    </contact>
    <inertial>
      <origin rpy="0 0 0" xyz="0 0 0"/>
      <mass value="0.5"/>
      <inertia ixx="1" ixy="0" ixz="0" iyy="1" iyz="0" izz="1"/>
    </inertial>
    <visual>
      <origin rpy="1.5708 0 0" xyz="120 0 -36"/>
      <geometry>
        <mesh filename="pps_leoni/interbras.obj" scale="1 1 1"/>
      </geometry>
      <material name="white">
        <color rgba="1 1 1 1"/>
      </material>
    </visual>
    <collision>
      <origin rpy="1.5708 0 0" xyz="120 0 -36"/>
      <geometry>
         <mesh filename="pps_leoni/interbras.obj" scale="1 1 1"/>
      </geometry>
    </collision>
  </link>
	<link name="A3">
    <contact>
      <lateral_friction value="1.0"/>
      <rolling_friction value="0.0"/>
      <contact_cfm value="0.0"/>
      <contact_erp value="1.0"/>
      <kd value ="1.0"/>
    </contact>
    <inertial>
      <origin rpy="0 0 0" xyz="31.129999 0 0"/>
      <mass value="0.5"/>
      <inertia ixx="1" ixy="0" ixz="0" iyy="1" iyz="0" izz="1"/>
    </inertial>
    <visual>
      <origin rpy="1.5708 0 0" xyz="86 0 -63"/>
      <geometry>
        <mesh filename="pps_leoni/BrasExtensionbras2.obj" scale="1 1 1"/>
      </geometry>
      <material name="white">
        <color rgba="1 1 1 1"/>
      </material>
    </visual>
    <collision>
		<origin rpy="1.5708 0 0" xyz="86 0 -63"/>
		<geometry>
			<mesh filename="pps_leoni/BrasExtensionbras2.obj" scale="1 1 1"/>
		</geometry>
    </collision>
  </link>

	<joint name="base" type="fixed">
    <parent link="isocenter"/>
    <child link="base"/>
	<origin xyz="0.000000 -195.000000 -110.300003" rpy="0 0 0" />
	</joint>
	
	<joint name="joint0" type="continuous">
    <dynamics damping="10000000" friction="10000000"/>
    <parent link="base"/>
    <child link="A1"/>
    <origin xyz="0 0 0" rpy="0 0 0" />
    <axis xyz="0 0 1"/>
	</joint>

	<joint name="joint1" type="continuous">
    <dynamics damping="10000000" friction="10000000"/>
    <parent link="A1"/>
    <child link="A2"/>
    <origin xyz="-120 0 36" rpy="0 0 0" />
    <axis xyz="0 0 1" />
	</joint>
    
	<joint name="joint2" type="continuous">
    <dynamics damping="10000000" friction="10000000"/>
    <parent link="A2"/>
    <child link="A3"/>
    <origin xyz="35 0 27" rpy="0 0 0" />
    <axis xyz="0 -1 0" />
	</joint>

</robot>

