<robot name="test_robot" xmlns:xacro="http://ros.org/wiki/xacro">

	<link name = "isocenter">
	<inertial>
      <origin rpy="0 0 0" xyz="0 0 0"/>
      <mass value="0.0"/>
      <inertia ixx="1" ixy="0" ixz="0" iyy="1" iyz="0" izz="1"/>
    </inertial>
    <visual>
      <origin rpy="0 0 0" xyz="0 0 0"/>
      <geometry>
		<box size="0.001 0.001 0.001"/>
	</geometry>
		<material name="red">
        <color rgba="1 0 0 1"/>
      </material>
    </visual>
    <!--<collision>
      <origin rpy="0 0 0" xyz="0 0 0"/>
      <geometry>
         <box size="0.001 0.001 0.001"/>
      </geometry>
    </collision>-->
  </link>

	<link name="base">
    <contact>
      <lateral_friction value="1.0"/>
      <rolling_friction value="0.0"/>
      <contact_cfm value="1.0"/>
      <contact_erp value="1.0"/>
    </contact>
    <inertial>
      <origin rpy="0 0 0"  xyz="0.000000 0 0"/>
      <mass value="292.0"/>
      <inertia ixx="1" ixy="0" ixz="0" iyy="1" iyz="0" izz="1"/>
    </inertial>
    <visual>
      <origin rpy="1.5708 0 0"  xyz="0 0 0"/>
      <geometry>
        <mesh filename="pps_leoni/pied.obj" scale="0.01 0.01 0.01"/>
      </geometry>
      <material name="white">
        <color rgba="1 1 1 1"/>
      </material>
    </visual>
	    <collision>
      <origin rpy="1.5708 0 0"  xyz="0.000000 0 0"/>
      <geometry>
         <mesh filename="pps_leoni/pied.obj" scale="0.01 0.01 0.01"/>
      </geometry>
    </collision>
  </link>

	<link name="A1">
    <contact>
		<lateral_friction value="1.0"/>
		<rolling_friction value = "101"/>
		<contact_cfm value="0.0"/>
		<contact_erp value="1.0"/>
		<kd value ="1.0"/>
	</contact>
    <inertial>
      <origin rpy="0 0 0" xyz="-0.55 0 0.3"/>
      <mass value="180"/>
      <inertia ixx="1" ixy="0" ixz="0" iyy="1" iyz="0" izz="1"/>
    </inertial>
    <visual>
      <origin rpy=" 1.5708 0 0" xyz="0 0 0"/>
      <geometry>
        <mesh filename="pps_leoni/bras1.obj" scale="0.01 0.01 0.01"/>
      </geometry>
      <material name="white">
        <color rgba="1 1 1 1"/>
      </material>
    </visual>
    <collision>
      <origin rpy="1.5708 0 0" xyz="0 0 0"/>
      <geometry>
         <mesh filename="pps_leoni/bras1.obj" scale="0.01 0.01 0.01"/>
      </geometry>
    </collision>
  </link>
	<link name="A2">
    <contact>
      <lateral_friction value="1.0"/>
      <rolling_friction value="0.0"/>
      <contact_cfm value="0.0"/>
      <contact_erp value="1.0"/>
      <kd value ="1.0"/>
    </contact>
    <inertial>
      <origin rpy="0 0 0" xyz="0.05 0 0.1935"/>
      <mass value="299"/>
      <inertia ixx="1" ixy="0" ixz="0" iyy="1" iyz="0" izz="1"/>
    </inertial>
    <visual>
     <origin rpy="1.5708 0 0" xyz="1.2 0 -0.4365"/>
      <geometry>
        <mesh filename="pps_leoni/interbras.obj" scale="0.01 0.01 0.01"/>
      </geometry>
      <material name="white">
        <color rgba="1 1 1 1"/>
      </material>
    </visual>
    <collision>
      <origin rpy="1.5708 0 0" xyz="1.2 0 -0.4365"/>
      <geometry>
         <mesh filename="pps_leoni/interbras.obj" scale="0.01 0.01 0.01"/>
      </geometry>
    </collision>
  </link>

	<link name="A3">
    <contact>
      <lateral_friction value="1.0"/>
      <rolling_friction value="0.0"/>
      <contact_cfm value="0.0"/>
      <contact_erp value="1.0"/>
      <kd value ="1.0"/>
    </contact>
    <inertial>
      <origin rpy="0 0 0" xyz="0.31129999 0 0"/>
      <mass value="193.2"/>
      <inertia ixx="1" ixy="0" ixz="0" iyy="1" iyz="0" izz="1"/>
    </inertial>
    <visual>
      <origin rpy="1.5708 0 0" xyz="0.85 0 -0.63"/>
      <geometry>
        <mesh filename="pps_leoni/BrasExtensionbras2.obj" scale="0.01 0.01 0.01"/>
      </geometry>
      <material name="white">
        <color rgba="1 1 1 1"/>
      </material>
    </visual>
    <collision>
		<origin rpy="1.5708 0 0" xyz="0.85 0 -0.63"/>
		<geometry>
			<mesh filename="pps_leoni/BrasExtensionbras2.obj" scale="0.01 0.01 0.01"/>
		</geometry>
    </collision>
  </link>

	<joint name="base" type="fixed">
	<dynamics damping="0.0" friction="0.0"/>
    <parent link="isocenter"/>
    <child link="base"/>
	<origin xyz="0.000000 -1.95 -1.25" rpy="0 0 0" />
	</joint>

	<joint name="joint0" type="continuous">
	<dynamics damping="0.0" friction="0.0"/>
    <parent link="base"/>
    <child link="A1"/>
    <origin xyz="0 0 0" rpy="0 0 0" />
    <axis xyz="0 0 1"/>
	</joint>

	<joint name="joint1" type="continuous">
	<dynamics damping="0.0" friction="0.0"/>
    <parent link="A1"/>
    <child link="A2"/>
    <origin xyz="-1.2 0 0.4365" rpy="0 0 0" />
    <axis xyz="0 0 1" />
	</joint>

	<joint name="joint2" type="continuous">
	<dynamics damping="0.0" friction="0.0"/>
    <parent link="A2"/>
    <child link="A3"/>
    <origin xyz="0.36 0 0.1935" rpy="0 0 0" />
    <axis xyz="0 -1 0" />
	</joint>

</robot>

